<?xml version="1.0"?>

<robot xmlns:sensor="http://playerstage.sourceforge.net/gazebo/xmlschema/#sensor"
xmlns:controller="http://playerstage.sourceforge.net/gazebo/xmlschema/#controller"
xmlns:interface="http://playerstage.sourceforge.net/gazebo/xmlschema/#interface"
xmlns:xacro="http://playerstage.sourceforge.net/gazebo/xmlschema/#interface"
>

  <xacro:macro name="gimbal_macro" params="namespace *origin">

    <link name="${namespace}/gimbal_link">
      <inertial>
        <mass value="0.1" />
        <inertia ixx="1e-4" ixy="0.0" ixz="0.0" iyy="1e-4" iyz="0.0" izz="1e-4" />
      </inertial>
    </link>

    <joint name="${namespace}/gimbal_joint" type="continuous">
      <parent link="${namespace}/base_link" />
      <child link="${namespace}/gimbal_link" />
      <origin xyz="0 0 0" rpy="0 0 0" />
      <axis xyz="0 1 0" />
    </joint>

    <gazebo>
      <plugin name="gimbal_controller" filename="libgimbal_plugin.so">
      </plugin>
    </gazebo>
  </xacro:macro>
</robot>